Workbook

Sheet KPI Calculation
I1: Metro(Mr. Sarath Hewanayaka) | X1: REGION 1(Mr. Harindra Atapattu) | AP1: Region 2(Mr. W.S.P.Welikada) | BE1: Region 3(Mr. M Pathmachuthan)
I2: Metro 1(Mr. Inesh Attanayaka) | R2: Metro 2(Mr. Lidira Guruge) | X2: WPN(Mr. Krishantha Sandaruwan) | AD2: NWP(Mr. Sanjaya Perera) | AJ2: CP(Mr. Rajiv Weragama) | AP2: SAB & UVA(Mr. Damitha Angunawala) | AV2: SP(Ms.Nilanka Menike) | BB2: WPS(Mr. Thisan Dammith) | BE2: EP(Mr. Y.Gobinath) | BH2: NP(Mr. S.M.J.M.Senanayake)
I3: NW/WPC1(Manjula) | L3: NW/WPC2(Ruwan) | O3: NW/WPE(Indika) | R3: NW/WP S-W(Karunananda) | U3: NW/WP S-E(Vishwajith) | X3: NW/WPN(Lansakkara) | AA3: NW/WP N-E(Kamal) | AD3: NW/NWP-E(Thilini) | AG3: NW/NWP-W(Thilanga) | AJ3: NW/CPN(Manora) | AM3: NW/CPS(Iranga) | AP3: NW/UVA(Roshan) | AS3: NW/SAB(Chintaka) | AV3: NW/SPE(Thilina) | AY3: NW/SPW(Wasantha) | BB3: WPS(Lalin) | BE3: NW/EP(Kishanthan) | BH3: NW/NP-1(Nandakumaran) | BK3: NW/NP-2(Puveehan) | BN3: NW/NCP(Dileepa)
I4: HK | L4: CEN/MD | O4: KON/KX | R4: ND/RM | U4: AW/HO | X4: NG/WT | AA4: GQ/KI/NTB | AD4: KG/KLY | AG4: CW/PX | AJ4: KY/MT | AM4: GP/HT/NW | AP4: BD/BW/MRG | AS4: KE/RN | AV4: EMB/HB/MH | AY4: AG/GL | BB4: HR/KT/PH | BE4: BC/AP/KL/TC | BH4: JA | BK4: KO/MLT/MB/VA | BN4: AD/PR
A5: #+A5:G20 | B5: Perspectives | C5: Strategic Objectives (KRA) | D5: Category | E5: Key Performance Indicators (KPI) | F5: Target | G5: Weightage | H5: Points Applicable | I5: Achieved KPI | J5: Maximum Points Per KPI | K5: Points Achieved | L5: Achieved KPI | M5: Maximum Points Per KPI | N5: Points Achieved | O5: Achieved KPI | P5: Maximum Points Per KPI | Q5: Points Achieved | R5: Achieved KPI | S5: Maximum Points Per KPI | T5: Points Achieved | U5: Achieved KPI | V5: Maximum Points Per KPI | W5: Points Achieved | X5: Achieved KPI | Y5: Maximum Points Per KPI | Z5: Points Achieved | AA5: Achieved KPI | AB5: Maximum Points Per KPI | AC5: Points Achieved | AD5: Achieved KPI | AE5: Maximum Points Per KPI | AF5: Points Achieved | AG5: Achieved KPI | AH5: Maximum Points Per KPI | AI5: Points Achieved | AJ5: Achieved KPI | AK5: Maximum Points Per KPI | AL5: Points Achieved | AM5: Achieved KPI | AN5: Maximum Points Per KPI | AO5: Points Achieved | AP5: Achieved KPI | AQ5: Maximum Points Per KPI | AR5: Points Achieved | AS5: Achieved KPI | AT5: Maximum Points Per KPI | AU5: Points Achieved | AV5: Achieved KPI | AW5: Maximum Points Per KPI | AX5: Points Achieved | AY5: Achieved KPI | AZ5: Maximum Points Per KPI | BA5: Points Achieved | BB5: Achieved KPI | BC5: Maximum Points Per KPI | BD5: Points Achieved | BE5: Achieved KPI | BF5: Maximum Points Per KPI | BG5: Points Achieved | BH5: Achieved KPI | BI5: Maximum Points Per KPI | BJ5: Points Achieved | BK5: Achieved KPI | BL5: Maximum Points Per KPI | BM5: Points Achieved | BN5: Achieved KPI | BO5: Maximum Points Per KPI | BP5: Points Achieved
A6: 1 | B6: Customer | C6: Service Assurance | D6: Transmission | E6: Fiber Failures Restoration(General): < 4 Hrs | F6: Above 85% | G6: =H6/$H$31 -> 0.088888889 | H6: 8000 | I6: ='OTN Operations'!G13 -> 1 | J6: =$H$6/20 -> 400 | K6: =IF('OTN Operations'!G14=0,'KPI Calculation'!$J$6,IF(I6>0.85,J6,J6*I6/0.85)) -> 400 | L6: ='OTN Operations'!H13 -> 1 | M6: =$H$6/20 -> 400 | N6: =IF('OTN Operations'!H14=0,M6,IF(L6>0.85,M6,M6*L6/0.85)) -> 400 | O6: ='OTN Operations'!L13 -> 1 | P6: =$H$6/20 -> 400 | Q6: =IF('OTN Operations'!L14=0,'KPI Calculation'!P6,IF(O6>0.85,P6,P6*O6/0.85)) -> 400 | R6: ='OTN Operations'!J13 -> 0.5 | S6: =$H$6/20 -> 400 | T6: =IF('OTN Operations'!J14=0,'KPI Calculation'!S6,IF(R6>0.85,S6,S6*R6/0.85)) -> 235.29412 | U6: ='OTN Operations'!K13 -> 0 | V6: =$H$6/20 -> 400 | W6: =IF('OTN Operations'!K14=0,'KPI Calculation'!V6,IF(U6>0.85,V6,V6*U6/0.85)) -> 0 | X6: ='OTN Operations'!M13 -> 0.75 | Y6: =$H$6/20 -> 400 | Z6: =IF('OTN Operations'!M14=0,'KPI Calculation'!Y6,IF(X6>0.85,Y6,Y6*X6/0.85)) -> 352.94118 | AA6: ='OTN Operations'!I13 -> 0.14285714 | AB6: =$H$6/20 -> 400 | AC6: =IF('OTN Operations'!I14=0,'KPI Calculation'!AB6,IF(AA6>0.85,AB6,AB6*AA6/0.85)) -> 67.226891 | AD6: ='OTN Operations'!N13 -> 1 | AE6: =$H$6/20 -> 400 | AF6: =IF('OTN Operations'!N14=0,'KPI Calculation'!AE6,IF(AD6>0.85,AE6,AE6*AD6/0.85)) -> 400 | AG6: ='OTN Operations'!O13 -> 0.8 | AH6: =$H$6/20 -> 400 | AI6: =IF('OTN Operations'!O14=0,'KPI Calculation'!AH6,IF(AG6>0.85,AH6,AH6*AG6/0.85)) -> 376.47059 | AJ6: ='OTN Operations'!P13 -> 1 | AK6: =$H$6/20 -> 400 | AL6: =IF('OTN Operations'!P14=0,'KPI Calculation'!AK6,IF(AJ6>0.85,AK6,AK6*AJ6/0.85)) -> 400 | AM6: ='OTN Operations'!Q13 -> 0.94642857 | AN6: =$H$6/20 -> 400 | AO6: =IF('OTN Operations'!Q14=0,'KPI Calculation'!AN6,IF(AM6>0.85,AN6,AN6*AM6/0.85)) -> 400 | AP6: ='OTN Operations'!S13 -> 1 | AQ6: =$H$6/20 -> 400 | AR6: =IF('OTN Operations'!S14=0,'KPI Calculation'!AQ6,IF(AP6>0.85,AQ6,AQ6*AP6/0.85)) -> 400 | AS6: ='OTN Operations'!T13 -> 1 | AT6: =$H$6/20 -> 400 | AU6: =IF('OTN Operations'!T14=0,'KPI Calculation'!AT6,IF(AS6>0.85,AT6,AT6*AS6/0.85)) -> 400 | AV6: ='OTN Operations'!U13 -> 0.25 | AW6: =$H$6/20 -> 400 | AX6: =IF('OTN Operations'!U14=0,'KPI Calculation'!AW6,IF(AW6>0.85,AW6,AW6*AV6/0.85)) -> 400 | AY6: ='OTN Operations'!V13 -> 1 | AZ6: =$H$6/20 -> 400 | BA6: =IF('OTN Operations'!V14=0,'KPI Calculation'!AZ6,IF(AY6>0.85,AZ6,AZ6*AY6/0.85)) -> 400 | BB6: ='OTN Operations'!W13 -> 1 | BC6: =$H$6/20 -> 400 | BD6: =IF('OTN Operations'!W14=0,'KPI Calculation'!BC6,IF(BB6>0.85,BC6,BC6*BB6/0.85)) -> 400 | BE6: ='OTN Operations'!X13 -> 1 | BF6: =$H$6/20 -> 400 | BG6: =IF('OTN Operations'!X14=0,'KPI Calculation'!BF6,IF(BE6>0.85,BF6,BF6*BE6/0.85)) -> 400 | BH6: ='OTN Operations'!Y13 -> 0.85714286 | BI6: =$H$6/20 -> 400 | BJ6: =IF('OTN Operations'!Y14=0,'KPI Calculation'!BI6,IF(BH6>0.85,BI6,BI6*BH6/0.85)) -> 400 | BK6: ='OTN Operations'!Z13 -> 1 | BL6: =$H$6/20 -> 400 | BM6: =IF('OTN Operations'!Z14=0,'KPI Calculation'!BL6,IF(BK6>0.85,BL6,BL6*BK6/0.85)) -> 400 | BN6: ='OTN Operations'!R13 -> 0.52941176 | BO6: =$H$6/20 -> 400 | BP6: =IF('OTN Operations'!R14=0,'KPI Calculation'!BO6,IF(BN6>0.85,BO6,BO6*BN6/0.85)) -> 249.13495
A7: 2 | B7: Customer | C7: Service Assurance | D7: Transmission | E7: Fiber Failures Restoration (Large scale< Pole damages etc>): < 8 Hrs | F7: Above 80% | G7: =H7/$H$31 -> 0.044444444 | H7: 4000 | I7: ='OTN Operations'!G16 -> 1 | J7: =$H$7/20 -> 200 | K7: =IF('OTN Operations'!G17=0,'KPI Calculation'!J7,(IF(I7>0.8,J7,J7*I7/0.8))) -> 200 | L7: ='OTN Operations'!H16 -> 1 | M7: =$H$7/20 -> 200 | N7: =IF('OTN Operations'!H17=0,'KPI Calculation'!M7,(IF(L7>0.8,M7,M7*L7/0.8))) -> 200 | O7: ='OTN Operations'!L16 -> 1 | P7: =$H$7/20 -> 200 | Q7: =IF('OTN Operations'!L17=0,'KPI Calculation'!P7,(IF(O7>0.8,P7,P7*O7/0.8))) -> 200 | R7: ='OTN Operations'!J16 -> 1 | S7: =$H$7/20 -> 200 | T7: =IF('OTN Operations'!J17=0,'KPI Calculation'!S7,(IF(R7>0.8,S7,S7*R7/0.8))) -> 200 | U7: ='OTN Operations'!K16 -> 0 | V7: =$H$7/20 -> 200 | W7: =IF('OTN Operations'!K17=0,'KPI Calculation'!V7,(IF(U7>0.8,V7,V7*U7/0.8))) -> 0 | X7: ='OTN Operations'!M16 -> 1 | Y7: =$H$7/20 -> 200 | Z7: =IF('OTN Operations'!M17=0,'KPI Calculation'!Y7,(IF(X7>0.8,Y7,Y7*X7/0.8))) -> 200 | AA7: ='OTN Operations'!I16 -> 1 | AB7: =$H$7/20 -> 200 | AC7: =IF('OTN Operations'!I17=0,'KPI Calculation'!AB7,(IF(AA7>0.8,AB7,AB7*AA7/0.8))) -> 200 | AD7: ='OTN Operations'!N16 -> 1 | AE7: =$H$7/20 -> 200 | AF7: =IF('OTN Operations'!N17=0,'KPI Calculation'!AE7,(IF(AD7>0.8,AE7,AE7*AD7/0.8))) -> 200 | AG7: ='OTN Operations'!O16 -> 1 | AH7: =$H$7/20 -> 200 | AI7: =IF('OTN Operations'!O17=0,'KPI Calculation'!AH7,(IF(AG7>0.8,AH7,AH7*AG7/0.8))) -> 200 | AJ7: ='OTN Operations'!P16 -> 0.9 | AK7: =$H$7/20 -> 200 | AL7: =IF('OTN Operations'!P17=0,'KPI Calculation'!AK7,(IF(AJ7>0.8,AK7,AK7*AJ7/0.8))) -> 200 | AM7: ='OTN Operations'!Q16 -> 0.83333333 | AN7: 181.5 | AO7: =IF('OTN Operations'!Q17=0,'KPI Calculation'!AN7,(IF(AM7>0.8,AN7,AN7*AM7/0.8))) -> 181.5 | AP7: ='OTN Operations'!S16 -> 1 | AQ7: =$H$7/20 -> 200 | AR7: =IF('OTN Operations'!S17=0,'KPI Calculation'!AQ7,(IF(AP7>0.8,AQ7,AQ7*AP7/0.8))) -> 200 | AS7: ='OTN Operations'!T16 -> 0.82142857 | AT7: =$H$7/20 -> 200 | AU7: =IF('OTN Operations'!T17=0,'KPI Calculation'!AT7,(IF(AS7>0.8,AT7,AT7*AS7/0.8))) -> 200 | AV7: ='OTN Operations'!U16 -> 0 | AW7: =$H$7/20 -> 200 | AX7: =IF('OTN Operations'!U17=0,'KPI Calculation'!AW7,(IF(AV7>0.8,AW7,AW7*AV7/0.8))) -> 0 | AY7: ='OTN Operations'!V16 -> 1 | AZ7: =$H$7/20 -> 200 | BA7: =IF('OTN Operations'!V17=0,'KPI Calculation'!AZ7,(IF(AY7>0.8,AZ7,AZ7*AY7/0.8))) -> 200 | BB7: ='OTN Operations'!W16 -> 0.875 | BC7: =$H$7/20 -> 200 | BD7: =IF('OTN Operations'!W17=0,'KPI Calculation'!BC7,(IF(BB7>0.8,BC7,BC7*BB7/0.8))) -> 200 | BE7: ='OTN Operations'!X16 -> 1 | BF7: =$H$7/20 -> 200 | BG7: =IF('OTN Operations'!X17=0,'KPI Calculation'!BF7,(IF(BE7>0.8,BF7,BF7*BE7/0.8))) -> 200 | BH7: ='OTN Operations'!Y16 -> 1 | BI7: =$H$7/20 -> 200 | BJ7: =IF('OTN Operations'!Y17=0,'KPI Calculation'!BI7,(IF(BH7>0.8,BI7,BI7*BH7/0.8))) -> 200 | BK7: ='OTN Operations'!Z16 -> 0.8 | BL7: =$H$7/20 -> 200 | BM7: =IF('OTN Operations'!Z17=0,'KPI Calculation'!BL7,(IF(BK7>0.8,BL7,BL7*BK7/0.8))) -> 200 | BN7: ='OTN Operations'!R16 -> 1 | BO7: =$H$7/20 -> 200 | BP7: =IF('OTN Operations'!R17=0,'KPI Calculation'!BO7,(IF(BN7>0.8,BO7,BO7*BN7/0.8))) -> 200
A8: 3 | B8: Customer | C8: Service Assurance | D8: Network Availability | E8: SLBN Node Availability | F8: 99.999% | G8: =H8/$H$31 -> 0.02 | H8: 1800 | I8: ='OTN Operations'!G5 -> 1 | J8: =$H$8*'OTN Operations'!G8/'OTN Operations'!$AA$8 -> 49.315068 | K8: =IF(I8>0.99999,J8,J8*I8/0.99999) -> 49.315068 | L8: ='OTN Operations'!H5 -> 1 | M8: =$H$8*'OTN Operations'!H8/'OTN Operations'!$AA$8 -> 73.972603 | N8: =IF(L8>0.99999,M8,M8*L8/0.99999) -> 73.972603 | O8: ='OTN Operations'!L5 -> 1 | P8: =$H$8*'OTN Operations'!L8/'OTN Operations'!$AA$8 -> 98.630137 | Q8: =IF(O8>0.99999,P8,P8*O8/0.99999) -> 98.630137 | R8: ='OTN Operations'!J5 -> 1 | S8: =$H$8*'OTN Operations'!J8/'OTN Operations'!$AA$8 -> 123.28767 | T8: =IF(R8>0.99999,S8,S8*R8/0.99999) -> 123.28767 | U8: ='OTN Operations'!K5 -> 1 | V8: =$H$8*'OTN Operations'!K8/'OTN Operations'!$AA$8 -> 73.972603 | W8: =IF(U8>0.99999,V8,V8*U8/0.99999) -> 73.972603 | X8: ='OTN Operations'!M5 -> 1 | Y8: =$H$8*'OTN Operations'!M8/'OTN Operations'!$AA$8 -> 147.94521 | Z8: =IF(X8>0.99999,Y8,Y8*X8/0.99999) -> 147.94521 | AA8: ='OTN Operations'!I5 -> 1 | AB8: =$H$8*'OTN Operations'!I16/'OTN Operations'!$AA$14 -> 11.111111 | AC8: =IF(AA8>0.99999,AB8,AB8*AA8/0.99999) -> 11.111111 | AD8: ='OTN Operations'!N5 -> 1 | AE8: =$H$8*'OTN Operations'!N8/'OTN Operations'!$AA$8 -> 49.315068 | AF8: =IF(AD8>0.99999,AE8,AE8*AD8/0.99999) -> 49.315068 | AG8: ='OTN Operations'!O5 -> 1 | AH8: =$H$8*'OTN Operations'!O8/'OTN Operations'!$AA$8 -> 24.657534 | AI8: =IF(AG8>0.99999,AH8,AH8*AG8/0.99999) -> 24.657534 | AJ8: ='OTN Operations'!P5 -> 1 | AK8: =$H$8*'OTN Operations'!P8/'OTN Operations'!$AA$8 -> 73.972603 | AL8: =IF(AJ8>0.99999,AK8,AK8*AJ8/0.99999) -> 73.972603 | AM8: ='OTN Operations'!Q5 -> 1 | AN8: =$H$8*'OTN Operations'!Q8/'OTN Operations'!$AA$8 -> 73.972603 | AO8: =IF(AM8>0.99999,AN8,AN8*AM8/0.99999) -> 73.972603 | AP8: ='OTN Operations'!S5 -> 1 | AQ8: =$H$8*'OTN Operations'!S8/'OTN Operations'!$AA$8 -> 73.972603 | AR8: =IF(AP8>0.99999,AQ8,AQ8*AP8/0.99999) -> 73.972603 | AS8: ='OTN Operations'!T5 -> 1 | AT8: =$H$8*'OTN Operations'!T8/'OTN Operations'!$AA$8 -> 147.94521 | AU8: =IF(AS8>0.99999,AT8,AT8*AS8/0.99999) -> 147.94521 | AV8: ='OTN Operations'!U5 -> 1 | AW8: =$H$8*'OTN Operations'!U8/'OTN Operations'!$AA$8 -> 98.630137 | AX8: =IF(AV8>0.99999,AW8,AW8*AV8/0.99999) -> 98.630137 | AY8: ='OTN Operations'!V5 -> 1 | AZ8: =$H$8*'OTN Operations'!V8/'OTN Operations'!$AA$8 -> 49.315068 | BA8: =IF(AY8>0.99999,AZ8,AZ8*AY8/0.99999) -> 49.315068 | BB8: ='OTN Operations'!W5 -> 1 | BC8: =$H$8*'OTN Operations'!W8/'OTN Operations'!$AA$8 -> 73.972603 | BD8: =IF(BB8>0.99999,BC8,BC8*BB8/0.99999) -> 73.972603 | BE8: ='OTN Operations'!X5 -> 1 | BF8: =$H$8*'OTN Operations'!X8/'OTN Operations'!$AA$8 -> 147.94521 | BG8: =IF(BE8>0.99999,BF8,BF8*BE8/0.99999) -> 147.94521 | BH8: ='OTN Operations'!Y5 -> 1 | BI8: =$H$8*'OTN Operations'!Y8/'OTN Operations'!$AA$8 -> 24.657534 | BJ8: =IF(BH8>0.99999,BI8,BI8*BH8/0.99999) -> 24.657534 | BK8: ='OTN Operations'!Z5 -> 1 | BL8: =$H$8*'OTN Operations'!Z8/'OTN Operations'!$AA$8 -> 147.94521 | BM8: =IF(BK8>0.99999,BL8,BL8*BK8/0.99999) -> 147.94521 | BN8: ='OTN Operations'!R5 -> 1 | BO8: =$H$8*'OTN Operations'!R8/'OTN Operations'!$AA$8 -> 147.94521 | BP8: =IF(BN8>0.99999,BO8,BO8*BN8/0.99999) -> 147.94521
A9: 4 | B9: Customer | C9: Service Assurance | D9: Network Availability | E9: IP Core Node Availability | F9: 99.999% | G9: =H9/$H$31 -> 0.02 | H9: 1800 | I9: ='IP NW Operations'!G6 -> 1 | J9: =$H$9*'IP NW Operations'!G9/'IP NW Operations'!AA9 -> 600 | K9: =IF(I9>0.99999,J9,J9*I9/0.99999) -> 600 | L9: ='IP NW Operations'!H6 -> 1 | M9: =$H$9*'IP NW Operations'!H9/'IP NW Operations'!$AA$9 -> 0 | N9: =IF(L9>0.99999,M9,M9*L9/0.99999) -> 0 | O9: ='IP NW Operations'!L6 -> 1 | P9: =$H$9*'IP NW Operations'!L9/'IP NW Operations'!$AA$9 -> 0 | Q9: =IF(O9>0.99999,P9,P9*O9/0.99999) -> 0 | R9: ='IP NW Operations'!J6 -> 1 | S9: =$H$9*'IP NW Operations'!J9/'IP NW Operations'!$AA$9 -> 0 | T9: =IF(R9>0.99999,S9,S9*R9/0.99999) -> 0 | U9: ='IP NW Operations'!K6 -> 1 | V9: =$H$9*'IP NW Operations'!K9/'IP NW Operations'!$AA$9 -> 0 | W9: =IF(U9>0.99999,V9,V9*U9/0.99999) -> 0 | X9: ='IP NW Operations'!M6 -> 1 | Y9: =$H$9*'IP NW Operations'!M9/'IP NW Operations'!$AA$9 -> 0 | Z9: =IF(X9>0.99999,Y9,Y9*X9/0.99999) -> 0 | AA9: ='IP NW Operations'!I6 -> 1 | AB9: =$H$9*'IP NW Operations'!I9/'IP NW Operations'!$AA$9 -> 0 | AC9: =IF(AA9>0.99999,AB9,AB9*AA9/0.99999) -> 0 | AD9: ='IP NW Operations'!N6 -> 1 | AE9: =$H$9*'IP NW Operations'!N9/'IP NW Operations'!$AA$9 -> 300 | AF9: =IF(AD9>0.99999,AE9,AE9*AD9/0.99999) -> 300 | AG9: ='IP NW Operations'!O6 -> 1 | AH9: =$H$9*'IP NW Operations'!O9/'IP NW Operations'!$AA$9 -> 0 | AI9: =IF(AG9>0.99999,AH9,AH9*AG9/0.99999) -> 0 | AJ9: ='IP NW Operations'!P6 -> 1 | AK9: =$H$9*'IP NW Operations'!P9/'IP NW Operations'!$AA$9 -> 300 | AL9: =IF(AJ9>0.99999,AK9,AK9*AJ9/0.99999) -> 300 | AM9: ='IP NW Operations'!Q6 -> 1 | AN9: =$H$9*'IP NW Operations'!Q9/'IP NW Operations'!$AA$9 -> 0 | AO9: =IF(AM9>0.99999,AN9,AN9*AM9/0.99999) -> 0 | AP9: ='IP NW Operations'!S6 -> 1 | AQ9: =$H$9*'IP NW Operations'!S9/'IP NW Operations'!$AA$9 -> 0 | AR9: =IF(AP9>0.99999,AQ9,AQ9*AP9/0.99999) -> 0 | AS9: ='IP NW Operations'!T6 -> 1 | AT9: =$H$9*'IP NW Operations'!T9/'IP NW Operations'!$AA$9 -> 300 | AU9: =IF(AS9>0.99999,AT9,AT9*AS9/0.99999) -> 300 | AV9: ='IP NW Operations'!U6 -> 1 | AW9: =$H$9*'IP NW Operations'!U9/'IP NW Operations'!$AA$9 -> 0 | AX9: =IF(AV9>0.99999,AW9,AW9*AV9/0.99999) -> 0 | AY9: ='IP NW Operations'!V6 -> 1 | AZ9: =$H$9*'IP NW Operations'!V9/'IP NW Operations'!$AA$9 -> 0 | BA9: =IF(AY9>0.99999,AZ9,AZ9*AY9/0.99999) -> 0 | BB9: ='IP NW Operations'!W6 -> 1 | BC9: =$H$9*'IP NW Operations'!W9/'IP NW Operations'!$AA$9 -> 300 | BD9: =IF(BB9>0.99999,BC9,BC9*BB9/0.99999) -> 300 | BE9: ='IP NW Operations'!X6 -> 1 | BF9: =$H$9*'IP NW Operations'!X9/'IP NW Operations'!$AA$9 -> 0 | BG9: =IF(BE9>0.99999,BF9,BF9*BE9/0.99999) -> 0 | BH9: ='IP NW Operations'!Y6 -> 1 | BI9: =$H$9*'IP NW Operations'!Y9/'IP NW Operations'!$AA$9 -> 0 | BJ9: =IF(BH9>0.99999,BI9,BI9*BH9/0.99999) -> 0 | BK9: ='IP NW Operations'!Z6 -> 1 | BL9: =$H$9*'IP NW Operations'!Z9/'IP NW Operations'!$AA$9 -> 0 | BM9: =IF(BK9>0.99999,BL9,BL9*BK9/0.99999) -> 0 | BN9: ='IP NW Operations'!R6 -> 1 | BO9: =$H$9*'IP NW Operations'!R9/'IP NW Operations'!$AA$9 -> 0 | BP9: =IF(BN9>0.99999,BO9,BO9*BN9/0.99999) -> 0
A10: 5 | B10: Customer | C10: Service Assurance | D10: Network Availability | E10: BSR Node availability | F10: 99.990% | G10: =H10/$H$31 -> 0.005 | H10: 450 | I10: ='IP NW Operations'!G10 -> 1 | J10: =$H$10*'IP NW Operations'!G13/'IP NW Operations'!$AA$13 -> 105.88235 | K10: =IF(I10>0.9999,J10,J10*I10/0.9999) -> 105.88235 | L10: ='IP NW Operations'!H10 -> 1 | M10: =$H$10*'IP NW Operations'!H13/'IP NW Operations'!$AA$13 -> 0 | N10: =IF(L10>0.9999,M10,M10*L10/0.9999) -> 0 | O10: ='IP NW Operations'!L10 -> 1 | P10: =$H$10*'IP NW Operations'!L13/'IP NW Operations'!$AA$13 -> 26.470588 | Q10: =IF(O10>0.9999,P10,P10*O10/0.9999) -> 26.470588 | R10: ='IP NW Operations'!J10 -> 1 | S10: =$H$10*'IP NW Operations'!J13/'IP NW Operations'!$AA$13 -> 26.470588 | T10: =IF(R10>0.9999,S10,S10*R10/0.9999) -> 26.470588 | U10: ='IP NW Operations'!K10 -> 1 | V10: =$H$10*'IP NW Operations'!K13/'IP NW Operations'!$AA$13 -> 26.470588 | W10: =IF(U10>0.9999,V10,V10*U10/0.9999) -> 26.470588 | X10: ='IP NW Operations'!M10 -> 1 | Y10: =$H$10*'IP NW Operations'!M13/'IP NW Operations'!$AA$13 -> 52.941176 | Z10: =IF(X10>0.9999,Y10,Y10*X10/0.9999) -> 52.941176 | AA10: ='IP NW Operations'!I10 -> 1 | AB10: =$H$10*'IP NW Operations'!I13/'IP NW Operations'!$AA$13 -> 26.470588 | AC10: =IF(AA10>0.9999,AB10,AB10*AA10/0.9999) -> 26.470588 | AD10: ='IP NW Operations'!N10 -> 1 | AE10: =$H$10*'IP NW Operations'!N13/'IP NW Operations'!$AA$13 -> 26.470588 | AF10: =IF(AD10>0.9999,AE10,AE10*AD10/0.9999) -> 26.470588 | AG10: ='IP NW Operations'!O10 -> 1 | AH10: =$H$10*'IP NW Operations'!O13/'IP NW Operations'!$AA$13 -> 0 | AI10: =IF(AG10>0.9999,AH10,AH10*AG10/0.9999) -> 0 | AJ10: ='IP NW Operations'!P10 -> 1 | AK10: =$H$10*'IP NW Operations'!P13/'IP NW Operations'!$AA$13 -> 26.470588 | AL10: =IF(AJ10>0.9999,AK10,AK10*AJ10/0.9999) -> 26.470588 | AM10: ='IP NW Operations'!Q10 -> 1 | AN10: =$H$10*'IP NW Operations'!Q13/'IP NW Operations'!$AA$13 -> 0 | AO10: =IF(AM10>0.9999,AN10,AN10*AM10/0.9999) -> 0 | AP10: ='IP NW Operations'!S10 -> 1 | AQ10: =$H$10*'IP NW Operations'!S13/'IP NW Operations'!$AA$13 -> 0 | AR10: =IF(AP10>0.9999,AQ10,AQ10*AP10/0.9999) -> 0 | AS10: ='IP NW Operations'!T10 -> 1 | AT10: =$H$10*'IP NW Operations'!T13/'IP NW Operations'!$AA$13 -> 26.470588 | AU10: =IF(AS10>0.9999,AT10,AT10*AS10/0.9999) -> 26.470588 | AV10: ='IP NW Operations'!U10 -> 1 | AW10: =$H$10*'IP NW Operations'!U13/'IP NW Operations'!$AA$13 -> 26.470588 | AX10: =IF(AV10>0.9999,AW10,AW10*AV10/0.9999) -> 26.470588 | AY10: ='IP NW Operations'!V10 -> 1 | AZ10: =$H$10*'IP NW Operations'!V13/'IP NW Operations'!$AA$13 -> 0 | BA10: =IF(AY10>0.9999,AZ10,AZ10*AY10/0.9999) -> 0 | BB10: ='IP NW Operations'!W10 -> 1 | BC10: =$H$10*'IP NW Operations'!W13/'IP NW Operations'!$AA$13 -> 26.470588 | BD10: =IF(BB10>0.9999,BC10,BC10*BB10/0.9999) -> 26.470588 | BE10: ='IP NW Operations'!X10 -> 1 | BF10: =$H$10*'IP NW Operations'!X13/'IP NW Operations'!$AA$13 -> 0 | BG10: =IF(BE10>0.9999,BF10,BF10*BE10/0.9999) -> 0 | BH10: ='IP NW Operations'!Y10 -> 1 | BI10: =$H$10*'IP NW Operations'!Y13/'IP NW Operations'!$AA$13 -> 26.470588 | BJ10: =IF(BH10>0.9999,BI10,BI10*BH10/0.9999) -> 26.470588 | BK10: ='IP NW Operations'!Z10 -> 1 | BL10: =$H$10*'IP NW Operations'!Z13/'IP NW Operations'!$AA$13 -> 0 | BM10: =IF(BK10>0.9999,BL10,BL10*BK10/0.9999) -> 0 | BN10: ='IP NW Operations'!R10 -> 1 | BO10: =$H$10*'IP NW Operations'!R13/'IP NW Operations'!$AA$13 -> 26.470588 | BP10: =IF(BN10>0.9999,BO10,BO10*BN10/0.9999) -> 26.470588
A11: 6 | B11: Customer | C11: Service Assurance | D11: Network Availability | E11: Service Edge Node availability | F11: 99.950% | G11: =H11/$H$31 -> 0.02 | H11: 1800 | I11: ='IP NW Operations'!G14 -> 1 | J11: =$H$11*'IP NW Operations'!G17/'IP NW Operations'!$AA$17 -> 81.663516 | K11: =IF(I11>0.9995,J11,J11*I11/0.9995) -> 81.663516 | L11: ='IP NW Operations'!H14 -> 1 | M11: =$H$11*'IP NW Operations'!H17/'IP NW Operations'!$AA$17 -> 309.64083 | N11: =IF(L11>0.9995,M11,M11*L11/0.9995) -> 309.64083 | O11: ='IP NW Operations'!L14 -> 1 | P11: =$H$11*'IP NW Operations'!L17/'IP NW Operations'!$AA$17 -> 146.3138 | Q11: =IF(O11>0.9995,P11,P11*O11/0.9995) -> 146.3138 | R11: ='IP NW Operations'!J14 -> 1 | S11: =$H$11*'IP NW Operations'!J17/'IP NW Operations'!$AA$17 -> 81.663516 | T11: =IF(R11>0.9995,S11,S11*R11/0.9995) -> 81.663516 | U11: ='IP NW Operations'!K14 -> 1 | V11: =$H$11*'IP NW Operations'!K17/'IP NW Operations'!$AA$17 -> 81.663516 | W11: =IF(U11>0.9995,V11,V11*U11/0.9995) -> 81.663516 | X11: ='IP NW Operations'!M14 -> 1 | Y11: =$H$11*'IP NW Operations'!M17/'IP NW Operations'!$AA$17 -> 102.0794 | Z11: =IF(X11>0.9995,Y11,Y11*X11/0.9995) -> 102.0794 | AA11: ='IP NW Operations'!I14 -> 1 | AB11: =$H$11*'IP NW Operations'!I17/'IP NW Operations'!$AA$17 -> 95.274102 | AC11: =IF(AA11>0.9995,AB11,AB11*AA11/0.9995) -> 95.274102 | AD11: ='IP NW Operations'!N14 -> 1 | AE11: =$H$11*'IP NW Operations'!N17/'IP NW Operations'!$AA$17 -> 81.663516 | AF11: =IF(AD11>0.9995,AE11,AE11*AD11/0.9995) -> 81.663516 | AG11: ='IP NW Operations'!O14 -> 1 | AH11: =$H$11*'IP NW Operations'!O17/'IP NW Operations'!$AA$17 -> 34.026465 | AI11: =IF(AG11>0.9995,AH11,AH11*AG11/0.9995) -> 34.026465 | AJ11: ='IP NW Operations'!P14 -> 1 | AK11: =$H$11*'IP NW Operations'!P17/'IP NW Operations'!$AA$17 -> 98.676749 | AL11: =IF(AJ11>0.9995,AK11,AK11*AJ11/0.9995) -> 98.676749 | AM11: ='IP NW Operations'!Q14 -> 0.99987007 | AN11: =$H$11*'IP NW Operations'!Q17/'IP NW Operations'!$AA$17 -> 85.066163 | AO11: =IF(AM11>0.9995,AN11,AN11*AM11/0.9995) -> 85.066163 | AP11: ='IP NW Operations'!S14 -> 1 | AQ11: =$H$11*'IP NW Operations'!S17/'IP NW Operations'!$AA$17 -> 64.650284 | AR11: =IF(AP11>0.9995,AQ11,AQ11*AP11/0.9995) -> 64.650284 | AS11: ='IP NW Operations'!T14 -> 0.99993969 | AT11: =$H$11*'IP NW Operations'!T17/'IP NW Operations'!$AA$17 -> 88.468809 | AU11: =IF(AS11>0.9995,AT11,AT11*AS11/0.9995) -> 88.468809 | AV11: ='IP NW Operations'!U14 -> 1 | AW11: =$H$11*'IP NW Operations'!U17/'IP NW Operations'!$AA$17 -> 108.88469 | AX11: =IF(AV11>0.9995,AW11,AW11*AV11/0.9995) -> 108.88469 | AY11: ='IP NW Operations'!V14 -> 1 | AZ11: =$H$11*'IP NW Operations'!V17/'IP NW Operations'!$AA$17 -> 51.039698 | BA11: =IF(AY11>0.9995,AZ11,AZ11*AY11/0.9995) -> 51.039698 | BB11: ='IP NW Operations'!W14 -> 1 | BC11: =$H$11*'IP NW Operations'!W17/'IP NW Operations'!$AA$17 -> 71.455577 | BD11: =IF(BB11>0.9995,BC11,BC11*BB11/0.9995) -> 71.455577 | BE11: ='IP NW Operations'!X14 -> 0.99679766 | BF11: =$H$11*'IP NW Operations'!X17/'IP NW Operations'!$AA$17 -> 71.455577 | BG11: =IF(BE11>0.9995,BF11,BF11*BE11/0.9995) -> 71.262383 | BH11: ='IP NW Operations'!Y14 -> 1 | BI11: =$H$11*'IP NW Operations'!Y17/'IP NW Operations'!$AA$17 -> 34.026465 | BJ11: =IF(BH11>0.9995,BI11,BI11*BH11/0.9995) -> 34.026465 | BK11: ='IP NW Operations'!Z14 -> 1 | BL11: =$H$11*'IP NW Operations'!Z17/'IP NW Operations'!$AA$17 -> 51.039698 | BM11: =IF(BK11>0.9995,BL11,BL11*BK11/0.9995) -> 51.039698 | BN11: ='IP NW Operations'!R14 -> 0.9994325 | BO11: =$H$11*'IP NW Operations'!R17/'IP NW Operations'!$AA$17 -> 91.871456 | BP11: =IF(BN11>0.9995,BO11,BO11*BN11/0.9995) -> 91.865251
A12: 7 | B12: Customer | C12: Service Assurance | D12: Network Availability | E12: International Backhaul Node Availability | F12: 0.99999 | G12: =H12/$H$31 -> 0.015 | H12: 1350 | I12: ='OTN Operations'!G27 -> 1 | J12: =$H$12*'OTN Operations'!G30/'OTN Operations'!$AA$30 -> 0 | K12: =IF(I12>0.99999,J12,J12*I12/0.99999) -> 0 | L12: ='OTN Operations'!H27 -> 1 | M12: =$H$12*'OTN Operations'!H30/'OTN Operations'!$AA$30 -> 450 | N12: =IF(L12>0.99999,M12,M12*L12/0.99999) -> 450 | O12: ='OTN Operations'!L27 -> 1 | P12: =$H$12*'OTN Operations'!L30/'OTN Operations'!$AA$30 -> 0 | Q12: =IF(O12>0.99999,P12,P12*O12/0.99999) -> 0 | R12: ='OTN Operations'!J27 -> 1 | S12: =$H$12*'OTN Operations'!J30/'OTN Operations'!$AA$30 -> 225 | T12: =IF(R12>0.99999,S12,S12*R12/0.99999) -> 225 | U12: ='OTN Operations'!K27 -> 1 | V12: =$H$12*'OTN Operations'!K30/'OTN Operations'!$AA$30 -> 56.25 | W12: =IF(U12>0.99999,V12,V12*U12/0.99999) -> 56.25 | X12: ='OTN Operations'!M27 -> 1 | Y12: =$H$12*'OTN Operations'!M30/'OTN Operations'!$AA$30 -> 0 | Z12: =IF(X12>0.99999,Y12,Y12*X12/0.99999) -> 0 | AA12: ='OTN Operations'!I27 -> 1 | AB12: =$H$12*'OTN Operations'!I30/'OTN Operations'!$AA$30 -> 0 | AC12: =IF(AA12>0.99999,AB12,AB12*AA12/0.99999) -> 0 | AD12: ='OTN Operations'!N27 -> 1 | AE12: =$H$12*'OTN Operations'!N30/'OTN Operations'!$AA$30 -> 0 | AF12: =IF(AD12>0.99999,AE12,AE12*AD12/0.99999) -> 0 | AG12: ='OTN Operations'!O27 -> 1 | AH12: =$H$12*'OTN Operations'!O30/'OTN Operations'!$AA$30 -> 0 | AI12: =IF(AG12>0.99999,AH12,AH12*AG12/0.99999) -> 0 | AJ12: ='OTN Operations'!P27 -> 1 | AK12: =$H$12*'OTN Operations'!P30/'OTN Operations'!$AA$30 -> 0 | AL12: =IF(AJ12>0.99999,AK12,AK12*AJ12/0.99999) -> 0 | AM12: ='OTN Operations'!Q27 -> 1 | AN12: =$H$12*'OTN Operations'!Q30/'OTN Operations'!$AA$30 -> 0 | AO12: =IF(AM12>0.99999,AN12,AN12*AM12/0.99999) -> 0 | AP12: ='OTN Operations'!S27 -> 1 | AQ12: =$H$12*'OTN Operations'!S30/'OTN Operations'!$AA$30 -> 0 | AR12: =IF(AP12>0.99999,AQ12,AQ12*AP12/0.99999) -> 0 | AS12: ='OTN Operations'!T27 -> 1 | AT12: =$H$12*'OTN Operations'!T30/'OTN Operations'!$AA$30 -> 56.25 | AU12: =IF(AS12>0.99999,AT12,AT12*AS12/0.99999) -> 56.25 | AV12: ='OTN Operations'!U27 -> 1 | AW12: =$H$12*'OTN Operations'!U30/'OTN Operations'!$AA$30 -> 365.625 | AX12: =IF(AV12>0.99999,AW12,AW12*AV12/0.99999) -> 365.625 | AY12: ='OTN Operations'!V27 -> 1 | AZ12: =$H$12*'OTN Operations'!V30/'OTN Operations'!$AA$30 -> 112.5 | BA12: =IF(AY12>0.99999,AZ12,AZ12*AY12/0.99999) -> 112.5 | BB12: ='OTN Operations'!W27 -> 1 | BC12: =$H$12*'OTN Operations'!W30/'OTN Operations'!$AA$30 -> 84.375 | BD12: =IF(BB12>0.99999,BC12,BC12*BB12/0.99999) -> 84.375 | BE12: ='OTN Operations'!X27 -> 1 | BF12: =$H$12*'OTN Operations'!X30/'OTN Operations'!$AA$30 -> 0 | BG12: =IF(BE12>0.99999,BF12,BF12*BE12/0.99999) -> 0 | BH12: ='OTN Operations'!Y27 -> 1 | BI12: =$H$12*'OTN Operations'!Y30/'OTN Operations'!$AA$30 -> 0 | BJ12: =IF(BH12>0.99999,BI12,BI12*BH12/0.99999) -> 0 | BK12: ='OTN Operations'!Z27 -> 1 | BL12: =$H$12*'OTN Operations'!Z16/'OTN Operations'!$AA$30 -> 22.5 | BM12: =IF(BK12>0.99999,BL12,BL12*BK12/0.99999) -> 22.5 | BN12: ='OTN Operations'!R27 -> 1 | BO12: =$H$12*'OTN Operations'!R30/'OTN Operations'!$AA$30 -> 0 | BP12: =IF(BN12>0.99999,BO12,BO12*BN12/0.99999) -> 0
A13: 8 | B13: Customer | C13: Service Assurance | D13: Network Availability | E13: MSAN/OLT Node Availability | F13: 0.9994 | G13: =H13/$H$31 -> 0.015 | H13: 1350 | I13: ='[1]Wireline Access NW Op'!G5 -> 0.9995 | J13: =$H$13*'[1]Wireline Access NW Op'!G11/'[1]Wireline Access NW Op'!$AA$11 -> 67.5 | K13: =IF(I13>0.9994,J13,J13*I13/0.9994) -> 67.5 | L13: ='[1]Wireline Access NW Op'!J5 -> 0.9996 | M13: =$H$13*'[1]Wireline Access NW Op'!J11/'[1]Wireline Access NW Op'!$AA$11 -> 67.5 | N13: =IF(L13>0.9994,M13,M13*L13/0.9994) -> 67.5 | O13: ='[1]Wireline Access NW Op'!M5 -> 0.9995 | P13: =$H$13*'[1]Wireline Access NW Op'!M11/'[1]Wireline Access NW Op'!$AA$11 -> 67.5 | Q13: =IF(O13>0.9994,P13,P13*O13/0.9994) -> 67.5 | R13: ='[1]Wireline Access NW Op'!P5 -> 0.9996 | S13: =$H$13*'[1]Wireline Access NW Op'!P11/'[1]Wireline Access NW Op'!$AA$11 -> 67.5 | T13: =IF(R13>0.9994,S13,S13*R13/0.9994) -> 67.5 | U13: ='[1]Wireline Access NW Op'!S5 -> 0.9996 | V13: =$H$13*'[1]Wireline Access NW Op'!S11/'[1]Wireline Access NW Op'!$AA$11 -> 67.5 | W13: =IF(U13>0.9994,V13,V13*U13/0.9994) -> 67.5 | X13: ='[1]Wireline Access NW Op'!V5 -> 0.9995 | Y13: =$H$13*'[1]Wireline Access NW Op'!V11/'[1]Wireline Access NW Op'!$AA$11 -> 67.5 | Z13: =IF(X13>0.9994,Y13,Y13*X13/0.9994) -> 67.5 | AA13: ='[1]Wireline Access NW Op'!Y5 -> 0.9997 | AB13: =$H$13*'[1]Wireline Access NW Op'!Y11/'[1]Wireline Access NW Op'!$AA$11 -> 67.5 | AC13: =IF(AA13>0.9994,AB13,AB13*AA13/0.9994) -> 67.5 | AD13: ='[1]Wireline Access NW Op'!N5 -> 0.9996 | AE13: =$H$13*'[1]Wireline Access NW Op'!N11/'[1]Wireline Access NW Op'!$AA$11 -> 67.5 | AF13: =IF(AD13>0.9994,AE13,AE13*AD13/0.9994) -> 67.5 | AG13: ='[1]Wireline Access NW Op'!O5 -> 0.9997 | AH13: =$H$13*'[1]Wireline Access NW Op'!O11/'[1]Wireline Access NW Op'!$AA$11 -> 67.5 | AI13: =IF(AG13>0.9994,AH13,AH13*AG13/0.9994) -> 67.5 | AJ13: ='[1]Wireline Access NW Op'!P5 -> 0.9996 | AK13: =$H$13*'[1]Wireline Access NW Op'!P11/'[1]Wireline Access NW Op'!$AA$11 -> 67.5 | AL13: =IF(AJ13>0.9994,AK13,AK13*AJ13/0.9994) -> 67.5 | AM13: ='[1]Wireline Access NW Op'!Q5 -> 0.9996 | AN13: =$H$13*'[1]Wireline Access NW Op'!Q11/'[1]Wireline Access NW Op'!$AA$11 -> 67.5 | AO13: =IF(AM13>0.9994,AN13,AN13*AM13/0.9994) -> 67.5 | AP13: ='[1]Wireline Access NW Op'!S5 -> 0.9996 | AQ13: =$H$13*'[1]Wireline Access NW Op'!S11/'[1]Wireline Access NW Op'!$AA$11 -> 67.5 | AR13: =IF(AP13>0.9994,AQ13,AQ13*AP13/0.9994) -> 67.5 | AS13: ='[1]Wireline Access NW Op'!T5 -> 0.9997 | AT13: =$H$13*'[1]Wireline Access NW Op'!T11/'[1]Wireline Access NW Op'!$AA$11 -> 67.5 | AU13: =IF(AS13>0.9994,AT13,AT13*AS13/0.9994) -> 67.5 | AV13: ='[1]Wireline Access NW Op'!U5 -> 0.9996 | AW13: =$H$13*'[1]Wireline Access NW Op'!U11/'[1]Wireline Access NW Op'!$AA$11 -> 67.5 | AX13: =IF(AV13>0.9994,AW13,AW13*AV13/0.9994) -> 67.5 | AY13: ='[1]Wireline Access NW Op'!V5 -> 0.9995 | AZ13: =$H$13*'[1]Wireline Access NW Op'!V11/'[1]Wireline Access NW Op'!$AA$11 -> 67.5 | BA13: =IF(AY13>0.9994,AZ13,AZ13*AY13/0.9994) -> 67.5 | BB13: ='[1]Wireline Access NW Op'!W5 -> 0.9996 | BC13: =$H$13*'[1]Wireline Access NW Op'!W11/'[1]Wireline Access NW Op'!$AA$11 -> 67.5 | BD13: =IF(BB13>0.9994,BC13,BC13*BB13/0.9994) -> 67.5 | BE13: ='[1]Wireline Access NW Op'!X5 -> 0.9996 | BF13: =$H$13*'[1]Wireline Access NW Op'!X11/'[1]Wireline Access NW Op'!$AA$11 -> 67.5 | BG13: =IF(BE13>0.9994,BF13,BF13*BE13/0.9994) -> 67.5 | BH13: ='[1]Wireline Access NW Op'!Y5 -> 0.9997 | BI13: =$H$13*'[1]Wireline Access NW Op'!Y11/'[1]Wireline Access NW Op'!$AA$11 -> 67.5 | BJ13: =IF(BH13>0.9994,BI13,BI13*BH13/0.9994) -> 67.5 | BK13: ='[1]Wireline Access NW Op'!Z5 -> 0.9996 | BL13: =$H$13*'[1]Wireline Access NW Op'!Z11/'[1]Wireline Access NW Op'!$AA$11 -> 67.5 | BM13: =IF(BK13>0.9994,BL13,BL13*BK13/0.9994) -> 67.5 | BN13: ='[1]Wireline Access NW Op'!R5 -> 0.9995 | BO13: =$H$13*'[1]Wireline Access NW Op'!R11/'[1]Wireline Access NW Op'!$AA$11 -> 67.5 | BP13: =IF(BN13>0.9994,BO13,BO13*BN13/0.9994) -> 67.5
A14: 9 | B14: Customer | C14: Service Assurance | D14: Network Availability | E14: Telemetry Network Availability | F14: 0.9999 | G14: =H14/$H$31 -> 0.005 | H14: 450
A15: 10 | B15: Customer | C15: Service Assurance | D15: Routine Maintenance | E15: Routine maintenance - IPNW | F15: 1 | G15: =H15/$H$31 -> 0.036666667 | H15: 3300 | I15: 1 | J15: =$H$15*'Routine Maintenance'!J12/'Routine Maintenance'!$AX$12 -> 129.13043 | K15: =J15*I15 -> 129.13043 | L15: 1 | M15: =$H$15*'Routine Maintenance'!L12/'Routine Maintenance'!$AX$12 -> 552.3913 | N15: =M15*L15 -> 552.3913 | O15: 1 | P15: =$H$15*'Routine Maintenance'!T12/'Routine Maintenance'!$AX$12 -> 200.86957 | Q15: =P15*O15 -> 200.86957 | R15: 1 | S15: =$H$15*'Routine Maintenance'!P12/'Routine Maintenance'!$AX$12 -> 179.34783 | T15: =S15*R15 -> 179.34783 | U15: 1 | V15: =$H$15*'Routine Maintenance'!R12/'Routine Maintenance'!$AX$12 -> 100.43478 | W15: =V15*U15 -> 100.43478 | X15: 1 | Y15: =$H$15*'Routine Maintenance'!V12/'Routine Maintenance'!$AX$12 -> 215.21739 | Z15: =Y15*X15 -> 215.21739 | AA15: 1 | AB15: =$H$15*'Routine Maintenance'!N12/'Routine Maintenance'!$AX$12 -> 193.69565 | AC15: =AB15*AA15 -> 193.69565 | AD15: 1 | AE15: =$H$15*'Routine Maintenance'!X12/'Routine Maintenance'!$AX$12 -> 136.30435 | AF15: =AE15*AD15 -> 136.30435 | AG15: 1 | AH15: =$H$15*'Routine Maintenance'!Z12/'Routine Maintenance'!$AX$12 -> 64.565217 | AI15: =AH15*AG15 -> 64.565217 | AJ15: 1 | AK15: =$H$15*'Routine Maintenance'!AB12/'Routine Maintenance'!$AX$12 -> 186.52174 | AL15: =AK15*AJ15 -> 186.52174 | AM15: 1 | AN15: =$H$15*'Routine Maintenance'!AD12/'Routine Maintenance'!$AX$12 -> 165 | AO15: =AN15*AM15 -> 165 | AP15: 1 | AQ15: =$H$15*'Routine Maintenance'!AH12/'Routine Maintenance'!$AX$12 -> 114.78261 | AR15: =AQ15*AP15 -> 114.78261 | AS15: 1 | AT15: =$H$15*'Routine Maintenance'!AJ12/'Routine Maintenance'!$AX$12 -> 172.17391 | AU15: =AT15*AS15 -> 172.17391 | AV15: 1 | AW15: =$H$15*'Routine Maintenance'!AL12/'Routine Maintenance'!$AX$12 -> 243.91304 | AX15: =AW15*AV15 -> 243.91304 | AY15: 1 | AZ15: =$H$15*'Routine Maintenance'!AN12/'Routine Maintenance'!$AX$12 -> 93.26087 | BA15: =AZ15*AY15 -> 93.26087 | BB15: 1 | BC15: =$H$15*'Routine Maintenance'!AP12/'Routine Maintenance'!$AX$12 -> 129.13043 | BD15: =BC15*BB15 -> 129.13043 | BE15: 1 | BF15: =$H$15*'Routine Maintenance'!AR12/'Routine Maintenance'!$AX$12 -> 114.78261 | BG15: =BF15*BE15 -> 114.78261 | BH15: 1 | BI15: =$H$15*'Routine Maintenance'!AT12/'Routine Maintenance'!$AX$12 -> 50.217391 | BJ15: =BI15*BH15 -> 50.217391 | BK15: 1 | BL15: =$H$15*'Routine Maintenance'!AV12/'Routine Maintenance'!$AX$12 -> 100.43478 | BM15: =BL15*BK15 -> 100.43478 | BN15: 1 | BO15: =$H$15*'Routine Maintenance'!AF12/'Routine Maintenance'!$AX$12 -> 157.82609 | BP15: =BO15*BN15 -> 157.82609
A16: 11 | B16: Customer | C16: Service Assurance | D16: Routine Maintenance | E16: Routine maintenance - SLBN | F16: 1 | G16: =H16/$H$31 -> 0.036666667 | H16: 3300 | I16: 1 | J16: =$H$16*'Routine Maintenance'!J26/'Routine Maintenance'!$AX$26 -> 82.5 | K16: =J16*I16 -> 82.5 | L16: 1 | M16: =$H$16*'Routine Maintenance'!L26/'Routine Maintenance'!$AX$26 -> 165 | N16: =M16*L16 -> 165 | O16: 1 | P16: =$H$16*'Routine Maintenance'!T26/'Routine Maintenance'!$AX$26 -> 165 | Q16: =P16*O16 -> 165 | R16: 1 | S16: =$H$16*'Routine Maintenance'!P26/'Routine Maintenance'!$AX$26 -> 206.25 | T16: =S16*R16 -> 206.25 | U16: 1 | V16: =$H$16*'Routine Maintenance'!R26/'Routine Maintenance'!$AX$26 -> 123.75 | W16: =V16*U16 -> 123.75 | X16: 1 | Y16: =$H$16*'Routine Maintenance'!V26/'Routine Maintenance'!$AX$26 -> 288.75 | Z16: =Y16*X16 -> 288.75 | AA16: 1 | AB16: =$H$16*'Routine Maintenance'!N26/'Routine Maintenance'!$AX$26 -> 206.25 | AC16: =AB16*AA16 -> 206.25 | AD16: 1 | AE16: =$H$16*'Routine Maintenance'!X26/'Routine Maintenance'!$AX$26 -> 123.75 | AF16: =AE16*AD16 -> 123.75 | AG16: 1 | AH16: =$H$16*'Routine Maintenance'!Z26/'Routine Maintenance'!$AX$26 -> 41.25 | AI16: =AH16*AG16 -> 41.25 | AJ16: 1 | AK16: =$H$16*'Routine Maintenance'!AB26/'Routine Maintenance'!$AX$26 -> 165 | AL16: =AK16*AJ16 -> 165 | AM16: 1 | AN16: =$H$16*'Routine Maintenance'!AD26/'Routine Maintenance'!$AX$26 -> 123.75 | AO16: =AN16*AM16 -> 123.75 | AP16: 1 | AQ16: =$H$16*'Routine Maintenance'!AH26/'Routine Maintenance'!$AX$26 -> 123.75 | AR16: =AQ16*AP16 -> 123.75 | AS16: 1 | AT16: =$H$16*'Routine Maintenance'!AJ26/'Routine Maintenance'!$AX$26 -> 247.5 | AU16: =AT16*AS16 -> 247.5 | AV16: 1 | AW16: =$H$16*'Routine Maintenance'!AL26/'Routine Maintenance'!$AX$26 -> 206.25 | AX16: =AW16*AV16 -> 206.25 | AY16: 1 | AZ16: =$H$16*'Routine Maintenance'!AN26/'Routine Maintenance'!$AX$26 -> 82.5 | BA16: =AZ16*AY16 -> 82.5 | BB16: 1 | BC16: =$H$16*'Routine Maintenance'!AP26/'Routine Maintenance'!$AX$26 -> 123.75 | BD16: =BC16*BB16 -> 123.75 | BE16: 1 | BF16: =$H$16*'Routine Maintenance'!AR26/'Routine Maintenance'!$AX$26 -> 165 | BG16: =BF16*BE16 -> 165 | BH16: 1 | BI16: =$H$16*'Routine Maintenance'!AT26/'Routine Maintenance'!$AX$26 -> 41.25 | BJ16: =BI16*BH16 -> 41.25 | BK16: 1 | BL16: =$H$16*'Routine Maintenance'!AV26/'Routine Maintenance'!$AX$26 -> 330 | BM16: =BL16*BK16 -> 330 | BN16: 1 | BO16: =$H$16*'Routine Maintenance'!AF26/'Routine Maintenance'!$AX$26 -> 288.75 | BP16: =BO16*BN16 -> 288.75
A17: 12 | B17: Customer | C17: Service Assurance | D17: Routine Maintenance | E17: Routine maintenance - MSAN/OLT | F17: 1 | G17: =H17/$H$31 -> 0.026666667 | H17: 2400 | I17: 1 | J17: =$H$17*'Routine Maintenance'!J40/'Routine Maintenance'!$AX$40 -> 55.387616 | K17: =J17*I17 -> 55.387616 | L17: 1 | M17: =$H$17*'Routine Maintenance'!L40/'Routine Maintenance'!$AX$40 -> 85.811799 | N17: =M17*L17 -> 85.811799 | O17: 1 | P17: =$H$17*'Routine Maintenance'!T40/'Routine Maintenance'!$AX$40 -> 110.38518 | Q17: =P17*O17 -> 110.38518 | R17: 1 | S17: =$H$17*'Routine Maintenance'!P40/'Routine Maintenance'!$AX$40 -> 149.39054 | T17: =S17*R17 -> 149.39054 | U17: 1 | V17: =$H$17*'Routine Maintenance'!R40/'Routine Maintenance'!$AX$40 -> 95.56314 | W17: =V17*U17 -> 95.56314 | X17: 1 | Y17: =$H$17*'Routine Maintenance'!V40/'Routine Maintenance'!$AX$40 -> 170.84349 | Z17: =Y17*X17 -> 170.84349 | AA17: 1 | AB17: =$H$17*'Routine Maintenance'!N40/'Routine Maintenance'!$AX$40 -> 182.15505 | AC17: =AB17*AA17 -> 182.15505 | AD17: 1 | AE17: =$H$17*'Routine Maintenance'!X40/'Routine Maintenance'!$AX$40 -> 106.09459 | AF17: =AE17*AD17 -> 106.09459 | AG17: 1 | AH17: =$H$17*'Routine Maintenance'!Z40/'Routine Maintenance'!$AX$40 -> 70.599707 | AI17: =AH17*AG17 -> 70.599707 | AJ17: 1 | AK17: =$H$17*'Routine Maintenance'!AB40/'Routine Maintenance'!$AX$40 -> 230.5217 | AL17: =AK17*AJ17 -> 230.5217 | AM17: 1 | AN17: =$H$17*'Routine Maintenance'!AD40/'Routine Maintenance'!$AX40 -> 134.95856 | AO17: =AN17*AM17 -> 134.95856 | AP17: 1 | AQ17: =$H$17*'Routine Maintenance'!AH40/'Routine Maintenance'!$AX$40 -> 88.542175 | AR17: =AQ17*AP17 -> 88.542175 | AS17: 1 | AT17: =$H$17*'Routine Maintenance'!AJ40/'Routine Maintenance'!$AX$40 -> 155.24135 | AU17: =AT17*AS17 -> 155.24135 | AV17: 1 | AW17: =$H$17*'Routine Maintenance'!AL40/'Routine Maintenance'!$AX$40 -> 131.05802 | AX17: =AW17*AV17 -> 131.05802 | AY17: 1 | AZ17: =$H$17*'Routine Maintenance'!AN40/'Routine Maintenance'!$AX$40 -> 72.159922 | BA17: =AZ17*AY17 -> 72.159922 | BB17: 1 | BC17: =$H$17*'Routine Maintenance'!AP40/'Routine Maintenance'!$AX$40 -> 172.01365 | BD17: =BC17*BB17 -> 172.01365 | BE17: 1 | BF17: =$H$17*'Routine Maintenance'!AR40/'Routine Maintenance'!$AX$40 -> 108.82496 | BG17: =BF17*BE17 -> 108.82496 | BH17: 1 | BI17: =$H$17*'Routine Maintenance'!AT40/'Routine Maintenance'!$AX$40 -> 83.861531 | BJ17: =BI17*BH17 -> 83.861531 | BK17: 1 | BL17: =$H$17*'Routine Maintenance'!AV40/'Routine Maintenance'!$AX$40 -> 102.97416 | BM17: =BL17*BK17 -> 102.97416 | BN17: 1 | BO17: =$H$17*'Routine Maintenance'!AF40/'Routine Maintenance'!$AX$40 -> 93.612872 | BP17: =BO17*BN17 -> 93.612872
A18: 13 | B18: Customer | C18: Service Assurance | D18: Tower | E18: Operation & Maintenance of SLT towers and tower premises | F18: Above 95% | G18: =H18/$H$31 -> 0.011111111 | H18: 1000 | I18: =SUM('Tower Maintenance'!G7:G9) -> 0.83333333 | J18: =H18*'Tower Maintenance'!D31/'Tower Maintenance'!D39 -> 25.454545 | K18: =IF(I18>0.95,J18,J18*I18/0.95) -> 22.328549 | L18: =SUM('Tower Maintenance'!H7:H9) -> 0.6 | M18: =H18*'Tower Maintenance'!D32/'Tower Maintenance'!D39 -> 14.545455 | N18: =IF(L18>0.95,M18,M18*L18/0.95) -> 9.1866029 | O18: =SUM('Tower Maintenance'!L7:L9) -> 0.75 | P18: =H18*'Tower Maintenance'!D33/'Tower Maintenance'!D39 -> 14.545455 | Q18: =IF(O18>0.95,P18,P18*O18/0.95) -> 11.483254 | R18: =SUM('Tower Maintenance'!J7:J9) -> 1 | S18: =H18*'Tower Maintenance'!D38/'Tower Maintenance'!D39 -> 10.909091 | T18: =IF(R18>0.95,S18,S18*R18/0.95) -> 10.909091 | U18: =SUM('Tower Maintenance'!K7:K9) -> 0 | V18: =H18*'Tower Maintenance'!D37/'Tower Maintenance'!D39 -> 18.181818 | W18: =IF(U18>0.95,V18,V18*U18/0.95) -> 0 | X18: =SUM('Tower Maintenance'!M7:M9) -> 1 | Y18: =H18*'Tower Maintenance'!D34/'Tower Maintenance'!D39 -> 36.363636 | Z18: =IF(X18>0.95,Y18,Y18*X18/0.95) -> 36.363636 | AA18: =SUM('Tower Maintenance'!N7:N9) -> 0.81818182 | AB18: =H18*'Tower Maintenance'!D35/'Tower Maintenance'!D39 -> 40 | AC18: =IF(AA18>0.95,AB18,AB18*AA18/0.95) -> 34.449761 | AD18: =SUM('Tower Maintenance'!N7:N9) -> 0.81818182 | AE18: =H18*'Tower Maintenance'!D25/'Tower Maintenance'!D39 -> 40 | AF18: =IF(AD18>0.95,AE18,AE18*AD18/0.95) -> 34.449761 | AG18: =SUM('Tower Maintenance'!O7:O9) -> 1 | AH18: =H18*'Tower Maintenance'!D26/'Tower Maintenance'!D39 -> 32.727273 | AI18: =IF(AG18>0.95,AH18,AH18*AG18/0.95) -> 32.727273 | AJ18: =SUM('Tower Maintenance'!P7:P9) -> 0.92 | AK18: =H18*'Tower Maintenance'!D20/'Tower Maintenance'!D39 -> 83.636364 | AL18: =IF(AJ18>0.95,AK18,AK18*AJ18/0.95) -> 80.995215 | AM18: =SUM('Tower Maintenance'!Q7:Q9) -> 0.83333333 | AN18: =H18*'Tower Maintenance'!D21/'Tower Maintenance'!D39 -> 101.81818 | AO18: =IF(AM18>0.95,AN18,AN18*AM18/0.95) -> 89.314195 | AP18: =SUM('Tower Maintenance'!S7:S9) -> 1 | AQ18: =H18*'Tower Maintenance'!D30/'Tower Maintenance'!D39 -> 69.090909 | AR18: =IF(AP18>0.95,AQ18,AQ18*AP18/0.95) -> 69.090909 | AS18: =SUM('Tower Maintenance'!T7:T9) -> 1 | AT18: =H18*'Tower Maintenance'!D27/'Tower Maintenance'!D39 -> 40 | AU18: =IF(AS18>0.95,AT18,AT18*AS18/0.95) -> 40 | AV18: =SUM('Tower Maintenance'!U7:U9) -> 0.75 | AW18: =H18*'Tower Maintenance'!D28/'Tower Maintenance'!D39 -> 105.45455 | AX18: =IF(AV18>0.95,AW18,AW18*AV18/0.95) -> 83.253589 | AY18: =SUM('Tower Maintenance'!V7:V9) -> 1 | AZ18: =H18*'Tower Maintenance'!D29/'Tower Maintenance'!D39 -> 58.181818 | BA18: =IF(AY18>0.95,AZ18,AZ18*AY18/0.95) -> 58.181818 | BB18: =SUM('Tower Maintenance'!W7:W9) -> 1 | BC18: =H18*'Tower Maintenance'!D36/'Tower Maintenance'!D39 -> 18.181818 | BD18: =IF(BB18>0.95,BC18,BC18*BB18/0.95) -> 18.181818 | BE18: =SUM('Tower Maintenance'!X7:X9) -> 1 | BF18: =H18*'Tower Maintenance'!D19/'Tower Maintenance'!D39 -> 54.545455 | BG18: =IF(BE18>0.95,BF18,BF18*BE18/0.95) -> 54.545455 | BH18: =SUM('Tower Maintenance'!Y7:Y9) -> 1 | BI18: =H18*'Tower Maintenance'!D24/'Tower Maintenance'!D39 -> 36.363636 | BJ18: =IF(BH18>0.95,BI18,BI18*BH18/0.95) -> 36.363636 | BK18: =SUM('Tower Maintenance'!Z7:Z9) -> 1 | BL18: =H18*'Tower Maintenance'!D23/'Tower Maintenance'!D39 -> 101.81818 | BM18: =IF(BK18>0.95,BL18,BL18*BK18/0.95) -> 101.81818 | BN18: =SUM('Tower Maintenance'!R7:R9) -> 1 | BO18: =H18*'Tower Maintenance'!D22/'Tower Maintenance'!D39 -> 98.181818 | BP18: =IF(BN18>0.95,BO18,BO18*BN18/0.95) -> 98.181818
A19: 14 | B19: Customer | C19: Service Assurance | D19: Power & AC | E19: O&M of Power & Aircondition | F19: 0.9 | G19: =H19/$H$31 -> 0.055555556 | H19: 5000
A20: 15 | B20: Enterprise | C20: Service Assurance | D20: Other Operator | E20: Fault Rate (E/NW wise SLA) | F20: Variable Targets | G20: =H20/$H$31 -> 0.06 | H20: 5400
A21: 16 | B21: Enterprise | C21: Service Assurance | D21: Other Operator | E21: Repeated Fault Index (E/NW wise SLA) | F21: Variable Targets | G21: =H21/$H$31 -> 0.04 | H21: 3600
A22: 17 | B22: Enterprise | C22: Service Assurance | D22: Other Operator | E22: Fault Clearance Rate < 4 hrs | F22: 0.5 | G22: =H22/$H$31 -> 0.05 | H22: 4500
A23: 18 | B23: Enterprise | C23: Service Assurance | D23: Other Operator | E23: Fault Clearance Rate < 8 hrs | F23: 0.9 | G23: =H23/$H$31 -> 0.05 | H23: 4500
A24: 19 | B24: Enterprise | C24: Service Assurance | D24: Enteprise | E24: Fault Rate (E/NW wise SLA) | F24: Variable Targets | G24: =H24/$H$31 -> 0.03 | H24: 2700
A25: 20 | B25: Enterprise | C25: Service Assurance | D25: Enteprise | E25: Repeated Fault Index (E/NW wise SLA) | F25: Variable Targets | G25: =H25/$H$31 -> 0.02 | H25: 1800
A26: 21 | B26: Enterprise | C26: Service Assurance | D26: Enteprise | E26: Fault Clearance Rate < 4 hrs | F26: 0.9 | G26: =H26/$H$31 -> 0.05 | H26: 4500
A27: 22 | B27: Customer | C27: Service Fulfillment | D27: Serice Fulfillment | E27: Enterprise/SME and Whole Sales Service Delivery | G27: =H27/$H$31 -> 0.3 | H27: 27000 | I27: ='Service Fulfillment'!K18 -> 0.85238095 | J27: =$H$27/20 -> 1350 | K27: =J27*I27 -> 1150.7143 | L27: ='Service Fulfillment'!L18 -> 0.73478478 | M27: =$H$27/20 -> 1350 | N27: =M27*L27 -> 991.95946 | O27: ='Service Fulfillment'!P18 -> 0.94 | P27: =$H$27/20 -> 1350 | Q27: =P27*O27 -> 1269 | R27: ='Service Fulfillment'!N18 -> 0.97142857 | S27: =$H$27/20 -> 1350 | T27: =S27*R27 -> 1311.4286 | U27: ='Service Fulfillment'!O18 -> 0.9 | V27: =$H$27/20 -> 1350 | W27: =V27*U27 -> 1215 | X27: ='Service Fulfillment'!Q18 -> 0.86333333 | Y27: =$H$27/20 -> 1350 | Z27: =Y27*X27 -> 1165.5 | AA27: ='Service Fulfillment'!M18 -> 0.83333333 | AB27: =$H$27/20 -> 1350 | AC27: =AB27*AA27 -> 1125 | AD27: ='Service Fulfillment'!R18 -> 0.85 | AE27: =$H$27/20 -> 1350 | AF27: =AE27*AD27 -> 1147.5 | AG27: ='Service Fulfillment'!S18 -> 1 | AH27: =$H$27/20 -> 1350 | AI27: =AH27*AG27 -> 1350 | AJ27: ='Service Fulfillment'!T18 -> 1 | AK27: =$H$27/20 -> 1350 | AL27: =AK27*AJ27 -> 1350 | AM27: ='Service Fulfillment'!U18 -> 0.8 | AN27: =$H$27/20 -> 1350 | AO27: =AN27*AM27 -> 1080 | AP27: ='Service Fulfillment'!W18 -> 0.88333333 | AQ27: =$H$27/20 -> 1350 | AR27: =AQ27*AP27 -> 1192.5 | AS27: ='Service Fulfillment'!X18 -> 0.95 | AT27: =$H$27/20 -> 1350 | AU27: =AT27*AS27 -> 1282.5 | AV27: ='Service Fulfillment'!Y18 -> 0.92142857 | AW27: =$H$27/20 -> 1350 | AX27: =AW27*AV27 -> 1243.9286 | AY27: ='Service Fulfillment'!Z18 -> 0.98333333 | AZ27: =$H$27/20 -> 1350 | BA27: =AZ27*AY27 -> 1327.5 | BB27: ='Service Fulfillment'!AA18 -> 0.91666667 | BC27: =$H$27/20 -> 1350 | BD27: =BC27*BB27 -> 1237.5 | BE27: ='Service Fulfillment'!AB18 -> 1 | BF27: =$H$27/20 -> 1350 | BG27: =BF27*BE27 -> 1350 | BH27: ='Service Fulfillment'!AC18 -> 1 | BI27: =$H$27/20 -> 1350 | BJ27: =BI27*BH27 -> 1350 | BK27: ='Service Fulfillment'!AD18 -> 1 | BL27: =$H$27/20 -> 1350 | BM27: =BL27*BK27 -> 1350 | BN27: ='Service Fulfillment'!V18 -> 1 | BO27: =$H$27/20 -> 1350 | BP27: =BO27*BN27 -> 1350
G28: Total Marks | J28: =SUM(J6:J18) -> 1796.8335 | K28: =SUM(K6:K18) -> 1793.7075 | M28: =SUM(M6:M18) -> 2318.862 | N28: =SUM(N6:N18) -> 2313.5031 | P28: =SUM(P6:P18) -> 1429.7147 | Q28: =SUM(Q6:Q18) -> 1426.6525 | S28: =SUM(S6:S18) -> 1669.8192 | T28: =SUM(T6:T18) -> 1505.1134 | V28: =SUM(V6:V18) -> 1243.7864 | W28: =SUM(W6:W18) -> 625.60463 | Y28: =SUM(Y6:Y18) -> 1681.6403 | Z28: =SUM(Z6:Z18) -> 1634.5815 | AB28: =SUM(AB6:AB18) -> 1422.4565 | AC28: =SUM(AC6:AC18) -> 1084.1332 | AE28: =SUM(AE6:AE18) -> 1531.0981 | AF28: =SUM(AF6:AF18) -> 1525.5479 | AH28: =SUM(AH6:AH18) -> 935.3262 | AI28: =SUM(AI6:AI18) -> 911.79679 | AK28: =SUM(AK6:AK18) -> 1832.2997 | AL28: =SUM(AL6:AL18) -> 1829.6586 | AN28: =SUM(AN6:AN18) -> 1333.5655 | AO28: =SUM(AO6:AO18) -> 1321.0615 | AQ28: =SUM(AQ6:AQ18) -> 1202.2886 | AR28: =SUM(AR6:AR18) -> 1202.2886 | AT28: =SUM(AT6:AT18) -> 1901.5499 | AU28: =SUM(AU6:AU18) -> 1901.5499 | AW28: =SUM(AW6:AW18) -> 1953.786 | AX28: =SUM(AX6:AX18) -> 1731.5851 | AZ28: =SUM(AZ6:AZ18) -> 1186.4574 | BA28: =SUM(BA6:BA18) -> 1186.4574 | BC28: =SUM(BC6:BC18) -> 1666.8497 | BD28: =SUM(BD6:BD18) -> 1666.8497 | BF28: =SUM(BF6:BF18) -> 1330.0538 | BG28: =SUM(BG6:BG18) -> 1329.8606 | BI28: =SUM(BI6:BI18) -> 964.34715 | BJ28: =SUM(BJ6:BJ18) -> 964.34715 | BL28: =SUM(BL6:BL18) -> 1524.212 | BM28: =SUM(BM6:BM18) -> 1524.212 | BO28: =SUM(BO6:BO18) -> 1572.158 | BP28: =SUM(BP6:BP18) -> 1421.2868
G29: KPI | K29: =K28/J28 -> 0.99826027 | N29: =N28/M28 -> 0.99768902 | Q29: =Q28/P28 -> 0.99785817 | T29: =T28/S28 -> 0.90136305 | W29: =W28/V28 -> 0.50298396 | Z29: =Z28/Y28 -> 0.97201612 | AC29: =AC28/AB28 -> 0.76215557 | AF29: =AF28/AE28 -> 0.99637499 | AI29: =AI28/AH28 -> 0.97484363 | AL29: =AL28/AK28 -> 0.99855856 | AO29: =AO28/AN28 -> 0.99062364 | AR29: =AR28/AQ28 -> 1 | AU29: =AU28/AT28 -> 1 | AX29: =AX28/AW28 -> 0.8862716 | BA29: =BA28/AZ28 -> 1 | BD29: =BD28/BC28 -> 1 | BG29: =BG28/BF28 -> 0.99985475 | BJ29: =BJ28/BI28 -> 1 | BM29: =BM28/BL28 -> 1 | BP29: =BP28/BO28 -> 0.90403557
H31: =SUM(H6:H27) -> 90000
A39: 12 | B39: Customer | C39: Service Fullfillment | E39: Enterprise/ SME and Whole Sales Service Delivery - Fiber | F39: Above 95% | G39: =H39/$H$31 -> 0.38888889 | H39: 35000 | I39: ='OTN Operations'!G26 -> 0 | L39: ='OTN Operations'!H26 -> 0 | N39: 11.018824 | O39: ='OTN Operations'!L26 -> 0 | Q39: 11.08 | R39: ='OTN Operations'!J26 -> 0 | T39: 11.08 | U39: ='OTN Operations'!K26 -> 0 | W39: 11.034675 | X39: ='OTN Operations'!M26 -> 0 | Z39: 11 | AA39: ='OTN Operations'!I26 -> 0 | AC39: 11.01448 | AD39: ='OTN Operations'!N26 -> 0 | AF39: 11.08 | AG39: ='OTN Operations'!O26 -> 0 | AI39: 11.047059 | AJ39: ='OTN Operations'!P26 -> 0 | AL39: 11.08 | AM39: ='OTN Operations'!Q26 -> 0 | AO39: 11.08 | AP39: ='OTN Operations'!S26 -> 0 | AR39: 11.08 | AS39: ='OTN Operations'!T26 -> 0 | AU39: 11.08 | AV39: ='OTN Operations'!U26 -> 0 | AX39: 11.036199 | AY39: ='OTN Operations'!V26 -> 0 | BA39: 11.08 | BB39: ='OTN Operations'!W26 -> 0 | BD39: 11.08 | BE39: ='OTN Operations'!X26 -> 0 | BG39: 11.08 | BH39: ='OTN Operations'!Y26 -> 0 | BJ39: 11.08 | BK39: ='OTN Operations'!Z26 -> 0 | BM39: 11.08 | BN39: ='OTN Operations'!R26 -> 0 | BP39: 11.08

Sheet Service Assurance Faults
F1: Metro(Mr. Sarath Hewanayaka) | U1: REGION 1(Mr. Harindra Atapattu) | AM1: Region 2(Mr. W.S.P.Welikada) | BB1: Region 3(Mr. M Pathmachuthan)
F2: Metro 1(Mr. Inesh Attanayaka) | O2: Metro 2(Mr. Lidira Guruge) | U2: WPN(Mr. Krishantha Sandaruwan) | AA2: NWP(Mr. Sanjaya Perera) | AG2: CP(Mr. Rajiv Weragama) | AM2: SAB & UVA(Mr. Damitha Angunawala) | AS2: SP(Ms.Nilanka Menike) | AY2: WPS(Mr. Thisan Dammith) | BB2: EP(Mr. Y.Gobinath) | BE2: NP(Mr. S.M.J.M.Senanayake)
F3: NW/WPC1(Manjula) | I3: NW/WPC2(Ruwan) | L3: NW/WPE(Indika) | O3: NW/WP S-W(Karunananda) | R3: NW/WP S-E(Vishwajith) | U3: NW/WPN(Lansakkara) | X3: NW/WP N-E(Kamal) | AA3: NW/NWP-E(Thilini) | AD3: NW/NWP-W(Thilanga) | AG3: NW/CPN(Manora) | AJ3: NW/CPS(Iranga) | AM3: NW/UVA(Roshan) | AP3: NW/SAB(Chintaka) | AS3: NW/SPE(Thilina) | AV3: NW/SPW(Wasantha) | AY3: WPS(Lalin) | BB3: NW/EP(Kishanthan) | BE3: NW/NP-1(Nandakumaran) | BH3: NW/NP-2(Puveehan) | BK3: NW/NCP(Dileepa)
F4: HK | I4: CEN/MD | L4: KON/KX | O4: ND/RM | R4: AW/HO | U4: NG/WT | X4: GQ/KI/NTB | AA4: KG/KLY | AD4: CW/PX | AG4: KY/MT | AJ4: GP/HT/NW | AM4: BD/BW/MRG | AP4: KE/RN | AS4: EMB/HB/MH | AV4: AG/GL | AY4: HR/KT/PH | BB4: BC/AP/KL/TC | BE4: JA | BH4: KO/MLT/MB/VA | BK4: AD/PR
A5: #+A5:G20 | B5: Perspectives | C5: Strategic Objectives (KRA) | D5: Category | E5: Key Performance Indicators (KPI) | F5: Target | G5: Achievement | H5: KPI | I5: Achieved KPI | J5: Maximum Points Per KPI | K5: Points Achieved | L5: Achieved KPI | M5: Maximum Points Per KPI | N5: Points Achieved | O5: Achieved KPI | P5: Maximum Points Per KPI | Q5: Points Achieved | R5: Achieved KPI | S5: Maximum Points Per KPI | T5: Points Achieved | U5: Achieved KPI | V5: Maximum Points Per KPI | W5: Points Achieved | X5: Achieved KPI | Y5: Maximum Points Per KPI | Z5: Points Achieved | AA5: Achieved KPI | AB5: Maximum Points Per KPI | AC5: Points Achieved | AD5: Achieved KPI | AE5: Maximum Points Per KPI | AF5: Points Achieved | AG5: Achieved KPI | AH5: Maximum Points Per KPI | AI5: Points Achieved | AJ5: Achieved KPI | AK5: Maximum Points Per KPI | AL5: Points Achieved | AM5: Achieved KPI | AN5: Maximum Points Per KPI | AO5: Points Achieved | AP5: Achieved KPI | AQ5: Maximum Points Per KPI | AR5: Points Achieved | AS5: Achieved KPI | AT5: Maximum Points Per KPI | AU5: Points Achieved | AV5: Achieved KPI | AW5: Maximum Points Per KPI | AX5: Points Achieved | AY5: Achieved KPI | AZ5: Maximum Points Per KPI | BA5: Points Achieved | BB5: Achieved KPI | BC5: Maximum Points Per KPI | BD5: Points Achieved | BE5: Achieved KPI | BF5: Maximum Points Per KPI | BG5: Points Achieved | BH5: Achieved KPI | BI5: Maximum Points Per KPI | BJ5: Points Achieved | BK5: Achieved KPI | BL5: Maximum Points Per KPI | BM5: Points Achieved
A6: 16 | B6: Enterprise | C6: Service Assurance | D6: Other Operator | E6: Fault Rate (E/NW wise SLA) | H6: =IF(G6<F6,1,1-(G6-F6)/F6) -> #DIV/0!
A7: 17 | B7: Enterprise | C7: Service Assurance | D7: Other Operator | E7: Repeated Fault Index (E/NW wise SLA) | H7: =IF(G7<F7,1,1-(G7-F7)/F7) -> #DIV/0!
A8: 18 | B8: Enterprise | C8: Service Assurance | D8: Other Operator | E8: Fault Clearance Rate < 4 hrs | H8: =IF(G8>0.9,1,G8/0.9) -> 0
A9: 19 | B9: Enterprise | C9: Service Assurance | D9: Enteprise | E9: Fault Rate (E/NW wise SLA) | H9: =IF(G9<F9,1,1-(G9-F9)/F9) -> #DIV/0!
A10: 20 | B10: Enterprise | C10: Service Assurance | D10: Enteprise | E10: Repeated Fault Index (E/NW wise SLA) | H10: =IF(G10<F10,1,1-(G10-F10)/F10) -> #DIV/0!
A11: 21 | B11: Enterprise | C11: Service Assurance | D11: Enteprise | E11: Fault Clearance Rate < 4 hrs | H11: =IF(G11>0.9,1,G11/0.9) -> 0
G12: =SUM(#REF!) -> #REF! | H12: =SUM(#REF!) -> #REF! | J12: =SUM(#REF!) -> #REF! | K12: =SUM(#REF!) -> #REF! | M12: =SUM(#REF!) -> #REF! | N12: =SUM(#REF!) -> #REF! | P12: =SUM(#REF!) -> #REF! | Q12: =SUM(#REF!) -> #REF! | S12: =SUM(#REF!) -> #REF! | T12: =SUM(#REF!) -> #REF! | V12: =SUM(#REF!) -> #REF! | W12: =SUM(#REF!) -> #REF! | Y12: =SUM(#REF!) -> #REF! | Z12: =SUM(#REF!) -> #REF! | AB12: =SUM(#REF!) -> #REF! | AC12: =SUM(#REF!) -> #REF! | AE12: =SUM(#REF!) -> #REF! | AF12: =SUM(#REF!) -> #REF! | AH12: =SUM(#REF!) -> #REF! | AI12: =SUM(#REF!) -> #REF! | AK12: =SUM(#REF!) -> #REF! | AL12: =SUM(#REF!) -> #REF! | AN12: =SUM(#REF!) -> #REF! | AO12: =SUM(#REF!) -> #REF! | AQ12: =SUM(#REF!) -> #REF! | AR12: =SUM(#REF!) -> #REF! | AT12: =SUM(#REF!) -> #REF! | AU12: =SUM(#REF!) -> #REF! | AW12: =SUM(#REF!) -> #REF! | AX12: =SUM(#REF!) -> #REF! | AZ12: =SUM(#REF!) -> #REF! | BA12: =SUM(#REF!) -> #REF! | BC12: =SUM(#REF!) -> #REF! | BD12: =SUM(#REF!) -> #REF! | BF12: =SUM(#REF!) -> #REF! | BG12: =SUM(#REF!) -> #REF! | BI12: =SUM(#REF!) -> #REF! | BJ12: =SUM(#REF!) -> #REF! | BL12: =SUM(#REF!) -> #REF! | BM12: =SUM(#REF!) -> #REF!
H13: =H12/G12 -> #REF! | K13: =K12/J12 -> #REF! | N13: =N12/M12 -> #REF! | Q13: =Q12/P12 -> #REF! | T13: =T12/S12 -> #REF! | W13: =W12/V12 -> #REF! | Z13: =Z12/Y12 -> #REF! | AC13: =AC12/AB12 -> #REF! | AF13: =AF12/AE12 -> #REF! | AI13: =AI12/AH12 -> #REF! | AL13: =AL12/AK12 -> #REF! | AO13: =AO12/AN12 -> #REF! | AR13: =AR12/AQ12 -> #REF! | AU13: =AU12/AT12 -> #REF! | AX13: =AX12/AW12 -> #REF! | BA13: =BA12/AZ12 -> #REF! | BD13: =BD12/BC12 -> #REF! | BG13: =BG12/BF12 -> #REF! | BJ13: =BJ12/BI12 -> #REF! | BM13: =BM12/BL12 -> #REF!
A23: 12 | B23: Customer | C23: Service Fullfillment | E23: Enterprise/ SME and Whole Sales Service Delivery - Fiber | F23: ='OTN Operations'!G26 -> 0 | I23: ='OTN Operations'!H26 -> 0 | K23: 11.018824 | L23: ='OTN Operations'!L26 -> 0 | N23: 11.08 | O23: ='OTN Operations'!J26 -> 0 | Q23: 11.08 | R23: ='OTN Operations'!K26 -> 0 | T23: 11.034675 | U23: ='OTN Operations'!M26 -> 0 | W23: 11 | X23: ='OTN Operations'!I26 -> 0 | Z23: 11.01448 | AA23: ='OTN Operations'!N26 -> 0 | AC23: 11.08 | AD23: ='OTN Operations'!O26 -> 0 | AF23: 11.047059 | AG23: ='OTN Operations'!P26 -> 0 | AI23: 11.08 | AJ23: ='OTN Operations'!Q26 -> 0 | AL23: 11.08 | AM23: ='OTN Operations'!S26 -> 0 | AO23: 11.08 | AP23: ='OTN Operations'!T26 -> 0 | AR23: 11.08 | AS23: ='OTN Operations'!U26 -> 0 | AU23: 11.036199 | AV23: ='OTN Operations'!V26 -> 0 | AX23: 11.08 | AY23: ='OTN Operations'!W26 -> 0 | BA23: 11.08 | BB23: ='OTN Operations'!X26 -> 0 | BD23: 11.08 | BE23: ='OTN Operations'!Y26 -> 0 | BG23: 11.08 | BH23: ='OTN Operations'!Z26 -> 0 | BJ23: 11.08 | BK23: ='OTN Operations'!R26 -> 0 | BM23: 11.08

Sheet OTN Operations
A1: KPI(Fiber Failures Restoration,NW Availability-SLBN/SDH/FIBER NW/INTL BH) | F1: R-GM | G1: Metro | M1: REGION 1 | S1: Region 2 | X1: Region 3 | AA1: NW KPI
F2: P-DGM | G2: Metro 1 | J2: Metro 2 | M2: WPN & NWP | P2: CP & NCP | S2: SAB & UVA | U2: WPS & SP | X2: EP | Y2: NP
F3: NW EE | G3: NW/WPC1 | H3: NW/WPC2 | I3: NW/WP N-E | J3: NW/WP S-W | K3: NW/WP S-E | L3: NW/WPE | M3: NW/WPN | N3: NW/NWP-E | O3: NW/NWP-W | P3: NW/CPN | Q3: NW/CPS | R3: NW/NCP | S3: NW/UVA | T3: NW/SAB | U3: NW/SPE | V3: NW/SPW | W3: WPS | X3: NW/EP | Y3: NW/NP-1 | Z3: NW/NP-2
A4: No | B4: Network Engineers KPI's | C4: DIVISION | D4: SECTION | E4: KPI (%) | F4: RTOM AREA | G4: HK | H4: CEN/MD | I4: GQ/KI/NTB | J4: ND/RM | K4: AW/HO | L4: KON/KX | M4: NG/WT | N4: KG/KLY | O4: CW/PX | P4: DB/KY/MT | Q4: GP/HT/NW | R4: AD/PR | S4: BD/BW/MRG | T4: KE/RN | U4: EMB/HB/MH | V4: AG/GL | W4: HR/KT/PH | X4: BC/AP/KL/TC | Y4: JA | Z4: KO/MLT/MB/VA
A5: 8 | B5: SLBN NW Availability | C5: TRANSPORT & ACCESS | D5: BB&ANW | E5: 99.999 | G5: 1 | H5: 1 | I5: 1 | J5: 1 | K5: 1 | L5: 1 | M5: 1 | N5: 1 | O5: 1 | P5: 1 | Q5: 1 | R5: 1 | S5: 1 | T5: 1 | U5: 1 | V5: 1 | W5: 1 | X5: 1 | Y5: 1 | Z5: 1
B6: Unavailable NE minutes | G6: 0 | H6: 0 | I6: 0 | J6: 0 | K6: 0 | L6: 0 | M6: 0 | N6: 0 | O6: 0 | P6: 0 | Q6: 0 | R6: 0 | S6: 0 | T6: 0 | U6: 0 | V6: 0 | W6: 0 | X6: 0 | Y6: 0 | Z6: 0 | AA6: =SUM(G6:Z6) -> 0
B7: Total Minutes | G7: 86400 | H7: 223200 | I7: 267840 | J7: 223200 | K7: 133920 | L7: 178560 | M7: 267840 | N7: 89280 | O7: 44640 | P7: 133920 | Q7: 133920 | R7: 267840 | S7: 133920 | T7: 267840 | U7: 178560 | V7: 89280 | W7: 133920 | X7: 267840 | Y7: 44640 | Z7: 267840 | AA7: =SUM(G7:Z7) -> 3434400
B8: Total nodes | G8: 2 | H8: 3 | I8: 6 | J8: 5 | K8: 3 | L8: 4 | M8: 6 | N8: 2 | O8: 1 | P8: 3 | Q8: 3 | R8: 6 | S8: 3 | T8: 6 | U8: 4 | V8: 2 | W8: 3 | X8: 6 | Y8: 1 | Z8: 6 | AA8: =SUM(G8:Z8) -> 73
A9: 10 | B9: Fiber NW availability | C9: TRANSPORT & ACCESS | D9: BB&ANW | E9: 99.990 | G9: 0.9999829 | H9: 0.99986167 | I9: 0.99998524 | J9: 0.99981582 | K9: 0.99980034 | L9: 0.99994244 | M9: 0.99995285 | N9: 0.99972487 | O9: 0.99965063 | P9: 0.99983162 | Q9: 0.99938904 | R9: 0.99976741 | S9: 0.99994132 | T9: 0.99948744 | U9: 0.99983453 | V9: 0.99995104 | W9: 0.99989806 | X9: 0.99957776 | Y9: 0.99992279 | Z9: 0.99986006
B10: Unavailable Fiber Links minutes | G10: 5720 | H10: 4492 | I10: 6711 | J10: 739 | K10: 10512 | L10: 399 | M10: 19 | N10: 1634 | O10: 2228 | P10: 10694 | Q10: 27216 | R10: 14366 | S10: 1127 | T10: 9201 | U10: 3811 | V10: 2561 | W10: 737 | X10: 5374 | Y10: 357 | Z10: 4804 | AA10: =SUM(G10:Z10) -> 112702
B11: Total Fiber Links Minutes | G11: 259 | H11: 0 | I11: 11295 | J11: 435 | K11: 9004 | L11: 258 | M11: 1132 | N11: 2877 | O11: 1760 | P11: 10824 | Q11: 17588 | R11: 9355 | S11: 2166 | T11: 10127 | U11: 5643 | V11: 3533 | W11: 2993 | X11: 9448 | Y11: 1093 | Z11: 4268 | AA11: =SUM(G11:Z11) -> 104058
B12: Total Links | G12: 616 | H12: 616 | I12: 1219 | J12: 464 | K12: 470 | L12: 646 | M12: 439 | N12: 419 | O12: 151 | P12: 1407 | Q12: 417 | R12: 713 | S12: 457 | T12: 628 | U12: 750 | V12: 539 | W12: 848 | X12: 304 | Y12: 470 | Z12: 494 | AA12: =SUM(G12:Z12) -> 12067
A13: 12 | B13: Fiber Failures Restoration(General): <4 Hrs | C13: TRANSPORT & ACCESS | D13: INT & NT OP | E13: 0.85 | G13: 1 | H13: 1 | I13: 0.14285714 | J13: 0.5 | K13: 0 | L13: 1 | M13: 0.75 | N13: 1 | O13: 0.8 | P13: 1 | Q13: 0.94642857 | R13: 0.52941176 | S13: 1 | T13: 1 | U13: 0.25 | V13: 1 | W13: 1 | X13: 1 | Y13: 0.85714286 | Z13: 1
B14: Total Failed Links | G14: 0 | H14: 0 | I14: 7 | J14: 2 | K14: 5 | L14: 0 | M14: 4 | N14: 11 | O14: 5 | P14: 4 | Q14: 56 | R14: 17 | S14: 1 | T14: 0 | U14: 8 | V14: 4 | W14: 5 | X14: 0 | Y14: 7 | Z14: 26 | AA14: =SUM(G14:Z14) -> 162
B15: Links SLA Not Violated | G15: 0 | H15: 0 | I15: 1 | J15: 1 | K15: 0 | L15: 0 | M15: 3 | N15: 11 | O15: 4 | P15: 4 | Q15: 53 | R15: 9 | S15: 1 | T15: 0 | U15: 2 | V15: 4 | W15: 5 | X15: 0 | Y15: 6 | Z15: 26 | AA15: =SUM(G15:Z15) -> 130
A16: 13 | B16: Fiber Failures Restoration(Large scale< Pole damages etc>): <8 Hrs | C16: TRANSPORT & ACCESS | D16: INT & NT OP | E16: 0.8 | G16: 1 | H16: 1 | I16: 1 | J16: 1 | K16: 0 | L16: 1 | M16: 1 | N16: 1 | O16: 1 | P16: 0.9 | Q16: 0.83333333 | R16: 1 | S16: 1 | T16: 0.82142857 | U16: 0 | V16: 1 | W16: 0.875 | X16: 1 | Y16: 1 | Z16: 0.8
B17: Total Failed Links | G17: 1 | H17: 0 | I17: 0 | J17: 0 | K17: 8 | L17: 1 | M17: 0 | N17: 4 | O17: 1 | P17: 30 | Q17: 24 | R17: 15 | S17: 6 | T17: 28 | U17: 2 | V17: 8 | W17: 8 | X17: 31 | Y17: 0 | Z17: 5 | AA17: =SUM(G17:Z17) -> 172
B18: Links SLA Not Violated | G18: 1 | H18: 0 | I18: 0 | J18: 0 | K18: 0 | L18: 1 | M18: 0 | N18: 4 | O18: 1 | P18: 27 | Q18: 20 | R18: 15 | S18: 6 | T18: 23 | U18: 0 | V18: 8 | W18: 7 | X18: 31 | Y18: 0 | Z18: 4 | AA18: =SUM(G18:Z18) -> 148
B20: SDH and SLBN Links Failed Total
B21: SLBN & SDH NW <4 Hrs
B22: SLBN & SDH NW <8 Hrs
B23: NW faults in SLBN & SDH NW (General): <4 Hrs | C23: TRANSPORT & ACCESS | D23: INT & NT OP | E23: 100
B24: NW faults in SLBN & SDH NW (Large scale: <8 Hrs | C24: TRANSPORT & ACCESS | D24: INT & NT OP | E24: 100
